<?xml version="1.0" ?>
<robot name="aucar" xmlns:xacro="http://ros.org/wiki/xacro">
  <xacro:include filename="$(find aucar_description)/urdf/common_properties.xacro"/>
  <xacro:include filename="$(find aucar_description)/urdf/aucar.gazebo.xacro"/>

  <link name="base_footprint"/>

  <joint name="base_joint" type="fixed">
    <parent link="base_footprint"/>
    <child link="base_link"/>
    <origin xyz="0.0 0.0 0.0735" rpy="0 0 0"/>
  </joint>
  
  <link name="base_link">
    <visual>
      <origin xyz="-0.0044 0.0094 0.0016" rpy="0 0 0"/>
      <geometry>
        <mesh filename="package://aucar_description/mesh/waffle_plate.stl" scale="0.001 0.001 0.001"/>
      </geometry>
    </visual>
    <collision>
      <origin xyz="-0.0044 0.0094 0.0016" rpy="0 0 0"/>
      <geometry>
        <mesh filename="package://aucar_description/mesh/waffle_plate.stl" scale="0.001 0.001 0.001"/>
      </geometry>
    </collision>
    <inertial>
      <origin xyz="-0.0044 0.0094 0.0016" rpy="0 0 0"/>
      <mass value="1.5" />
      <inertia ixx="0.00391400" ixy="0.0" ixz="0.0"
               iyy="0.00391400" iyz="0.0"
               izz="0.00720300" />
    </inertial>


    <visual>
      <origin rpy="0 3.14159265359 -0.78539816339" xyz="0.064 0.064 0.0261"/>
      <geometry>
        <mesh filename="package://aucar_description/mesh/xl430.dae"/>
      </geometry>
    </visual>
    <collision>
      <origin rpy="0 3.14159265359 -0.78539816339" xyz="0.064 0.064 0.0261"/>
      <geometry>
        <mesh filename="package://aucar_description/mesh/xl430.dae"/>
      </geometry>
    </collision>
    <inertial>
      <origin rpy="0 3.14159265359 -0.78539816339" xyz="0.064 0.064 0.0261"/>
      <mass value="1.5" />
      <inertia ixx="0.00391400" ixy="0.0" ixz="0.0"
               iyy="0.00391400" iyz="0.0"
               izz="0.00720300" />
    </inertial>

    <visual>
      <origin rpy="0 3.14159265359 -2.35619449" xyz="0.064 -0.064 0.0261"/>
      <geometry>
        <mesh filename="package://aucar_description/mesh/xl430.dae"/>
      </geometry>
    </visual>
    <collision>
      <origin rpy="0 3.14159265359 -2.35619449" xyz="0.064 -0.064 0.0261"/>
      <geometry>
        <mesh filename="package://aucar_description/mesh/xl430.dae"/>
      </geometry>
    </collision>
    <inertial>
      <origin rpy="0 3.14159265359 -2.35619449" xyz="0.064 -0.064 0.0261"/>
      <mass value="1.5" />
      <inertia ixx="0.00391400" ixy="0.0" ixz="0.0"
               iyy="0.00391400" iyz="0.0"
               izz="0.00720300" />
    </inertial>

    <visual>
      <origin rpy="0 3.14159265359 0.78539816339" xyz="-0.064 0.064 0.0261"/>
      <geometry>
        <mesh filename="package://aucar_description/mesh/xl430.dae"/>
      </geometry>
    </visual>
    <collision>
      <origin rpy="0 3.14159265359 0.78539816339" xyz="-0.064 0.064 0.0261"/>
      <geometry>
        <mesh filename="package://aucar_description/mesh/xl430.dae"/>
      </geometry>
    </collision>
    <inertial>
      <origin rpy="0 3.14159265359 0.78539816339" xyz="-0.064 0.064 0.0261"/>
      <mass value="1.5" />
      <inertia ixx="0.00391400" ixy="0.0" ixz="0.0"
               iyy="0.00391400" iyz="0.0"
               izz="0.00720300" />
    </inertial>

    <visual>
      <origin rpy="0 3.14159265359 2.35619449" xyz="-0.064 -0.064 0.0261"/>
      <geometry>
        <mesh filename="package://aucar_description/mesh/xl430.dae"/>
      </geometry>
    </visual>
    <collision>
      <origin rpy="0 3.14159265359 2.35619449" xyz="-0.064 -0.064 0.0261"/>
      <geometry>
        <mesh filename="package://aucar_description/mesh/xl430.dae"/>
      </geometry>
    </collision>
    <inertial>
      <origin rpy="0 3.14159265359 2.35619449" xyz="-0.064 -0.064 0.0261"/>
      <mass value="1.5" />
      <inertia ixx="0.00391400" ixy="0.0" ixz="0.0"
               iyy="0.00391400" iyz="0.0"
               izz="0.00720300" />
    </inertial>

    <visual>
      <origin xyz="-0.0044 0.0094 0.0448" rpy="0 0 0"/>
      <geometry>
        <mesh filename="package://aucar_description/mesh/waffle_plate.stl" scale="0.001 0.001 0.001"/>
      </geometry>
    </visual>
    <collision>
      <origin xyz="-0.0044 0.0094 0.0448" rpy="0 0 0"/>
      <geometry>
        <mesh filename="package://aucar_description/mesh/waffle_plate.stl" scale="0.001 0.001 0.001"/>
      </geometry>
    </collision>
    <inertial>
      <origin xyz="-0.0044 0.0094 0.0448" rpy="0 0 0"/>
      <mass value="1.5" />
      <inertia ixx="0.00391400" ixy="0.0" ixz="0.0"
               iyy="0.00391400" iyz="0.0"
               izz="0.00720300" />
    </inertial>
  </link>

  <joint name="scan_joint" type="fixed">
    <parent link="base_link"/>
    <child link="scan_link"/>
    <origin xyz="0 0 0.038" rpy="0 0 0"/>
  </joint>

  <link name="scan_link">
    <visual>
      <origin xyz="0 0 0" rpy="1.570796327 0 1.570796327"/>
      <geometry>
        <mesh filename="package://aucar_description/mesh/sweep.stl" scale="0.001 0.001 0.001"/>
      </geometry>
    </visual>
    <collision>
      <origin xyz="0 0 0" rpy="1.570796327 0 1.570796327"/>
      <geometry>
        <mesh filename="package://aucar_description/mesh/sweep.stl" scale="0.001 0.001 0.001"/>
      </geometry>
    </collision>    
    <inertial>
      <origin xyz="0 0 0" rpy="1.570796327 0 1.570796327"/>
      <mass value="1.5" />
      <inertia ixx="0.00391400" ixy="0.0" ixz="0.0"
               iyy="0.00391400" iyz="0.0"
               izz="0.00720300" />
    </inertial>
  </link>

  <!--                                                         -->
  <!--                      steer layer                        -->
  <!--                                                         -->  
  <joint name="steer_left_front_joint" type="revolute">
    <parent link="base_link"/>
    <child link="steer_left_front_link"/>
    <origin rpy="0 0 0" xyz="0.064 0.064 0.007"/>
    <axis xyz="0 0 1" />
    <limit lower="0.0" upper="1.0" effort="10.0"
         velocity="5.0" />
  </joint>

  <link name="steer_left_front_link">
    <visual>
      <origin xyz="0.0 0.027 -0.047" rpy="1.570796327 3.14159265359 0"/>
      <geometry>
        <mesh filename="package://aucar_description/mesh/xl430.dae"/>
      </geometry>
    </visual>
    <collision>
      <origin xyz="0.0 0.027 -0.047" rpy="1.570796327 3.14159265359 0"/>
      <geometry>
        <mesh filename="package://aucar_description/mesh/xl430.dae"/>
      </geometry>
    </collision>
    <inertial>
      <origin xyz="0.0 0.027 -0.047" rpy="1.570796327 3.14159265359 0"/>
      <mass value="1.5" />
      <inertia ixx="0.00391400" ixy="0.0" ixz="0.0"
               iyy="0.00391400" iyz="0.0"
               izz="0.00720300" />
    </inertial>
  </link>

  <joint name="wheel_left_front_joint" type="continuous">
    <parent link="steer_left_front_link"/>
    <child link="wheel_left_front"/>
    <origin xyz="0.0 0.008 -0.047" rpy="0 0 0"/>
    <axis xyz="0 -1 0"/>
  </joint>

  <link name="wheel_left_front">
    <visual>
      <origin rpy="0 0 3.14159265359" xyz="0 -0.009 0"/>
      <geometry>
        <mesh filename="package://aucar_description/mesh/aucar_wheel.dae"/>
      </geometry>
    </visual>
    <collision>
      <origin rpy="0 0 3.14159265359" xyz="0 -0.009 0"/>
      <geometry>
        <mesh filename="package://aucar_description/mesh/aucar_wheel.dae"/>
      </geometry>
    </collision>
    <inertial>
      <origin rpy="0 0 3.14159265359" xyz="0 -0.009 0"/>
      <mass value="1.5" />
      <inertia ixx="0.00391400" ixy="0.0" ixz="0.0"
               iyy="0.00391400" iyz="0.0"
               izz="0.00720300" />
    </inertial>
  </link>


  <joint name="steer_right_front_joint" type="fixed">
    <parent link="base_link"/>
    <child link="steer_right_front_link"/>
    <origin rpy="0 0 0" xyz="0.064 -0.064 0.007"/>
    <axis xyz="0 0 1" />
  </joint>

  <link name="steer_right_front_link">
    <visual>
      <origin xyz="0.0 -0.027 -0.047" rpy="1.570796327 3.14159265359 0"/>
      <geometry>
        <mesh filename="package://aucar_description/mesh/xl430.dae"/>
      </geometry>
    </visual>
    <collision>
      <origin xyz="0.0 -0.027 -0.047" rpy="1.570796327 3.14159265359 0"/>
      <geometry>
        <mesh filename="package://aucar_description/mesh/xl430.dae"/>
      </geometry>
    </collision>
    <inertial>
      <origin xyz="0.0 -0.027 -0.047" rpy="1.570796327 3.14159265359 0"/>
      <mass value="1.5" />
      <inertia ixx="0.00391400" ixy="0.0" ixz="0.0"
               iyy="0.00391400" iyz="0.0"
               izz="0.00720300" />
    </inertial>
  </link>

  <joint name="wheel_right_front_joint" type="continuous">
    <parent link="steer_right_front_link"/>
    <child link="wheel_right_front"/>
    <origin xyz="0.0 -0.008 -0.047" rpy="0 0 0"/>
    <axis xyz="0 -1 0"/>
  </joint>

  <link name="wheel_right_front">
    <visual>
      <origin rpy="0 0 0" xyz="0 0.009 0"/>
      <geometry>
        <mesh filename="package://aucar_description/mesh/aucar_wheel.dae"/>
      </geometry>
    </visual>
    <collision>
      <origin rpy="0 0 0" xyz="0 0.009 0"/>
      <geometry>
        <mesh filename="package://aucar_description/mesh/aucar_wheel.dae"/>
      </geometry>
    </collision>
    <inertial>
      <origin rpy="0 0 0" xyz="0 0.009 0"/>
      <mass value="1.5" />
      <inertia ixx="0.00391400" ixy="0.0" ixz="0.0"
               iyy="0.00391400" iyz="0.0"
               izz="0.00720300" />
    </inertial>
  </link>


  <joint name="steer_left_rear_joint" type="fixed">
    <parent link="base_link"/>
    <child link="steer_left_rear_link"/>
    <origin rpy="0 0 0" xyz="-0.064 0.064 0.007"/>
    <axis xyz="0 0 1" />
  </joint>

  <link name="steer_left_rear_link">
    <visual>
      <origin xyz="0.0 0.027 -0.047" rpy="1.570796327 3.14159265359 0"/>
      <geometry>
        <mesh filename="package://aucar_description/mesh/xl430.dae"/>
      </geometry>
    </visual>
    <collision>
      <origin xyz="0.0 0.027 -0.047" rpy="1.570796327 3.14159265359 0"/>
      <geometry>
        <mesh filename="package://aucar_description/mesh/xl430.dae"/>
      </geometry>
    </collision>
    <inertial>
      <origin xyz="0.0 0.027 -0.047" rpy="1.570796327 3.14159265359 0"/>
      <mass value="1.5" />
      <inertia ixx="0.00391400" ixy="0.0" ixz="0.0"
               iyy="0.00391400" iyz="0.0"
               izz="0.00720300" />
    </inertial>
  </link>

  <joint name="wheel_left_rear_joint" type="continuous">
    <parent link="steer_left_rear_link"/>
    <child link="wheel_left_rear"/>
    <origin xyz="0.0 0.008 -0.047" rpy="0 0 0"/>
    <axis xyz="0 -1 0"/>
  </joint>

  <link name="wheel_left_rear">
    <visual>
      <origin rpy="0 0 3.14159265359" xyz="0 -0.009 0"/>
      <geometry>
        <mesh filename="package://aucar_description/mesh/aucar_wheel.dae"/>
      </geometry>
    </visual>
    <collision>
      <origin rpy="0 0 3.14159265359" xyz="0 -0.009 0"/>
      <geometry>
        <mesh filename="package://aucar_description/mesh/aucar_wheel.dae"/>
      </geometry>
    </collision>
    <inertial>
      <origin rpy="0 0 3.14159265359" xyz="0 -0.009 0"/>
      <mass value="1.5" />
      <inertia ixx="0.00391400" ixy="0.0" ixz="0.0"
               iyy="0.00391400" iyz="0.0"
               izz="0.00720300" />
    </inertial>
  </link> 


  <joint name="steer_right_rear_joint" type="fixed">
    <parent link="base_link"/>
    <child link="steer_right_rear_link"/>
    <origin rpy="0 0 0" xyz="-0.064 -0.064 0.007"/>
    <axis xyz="0 0 1" />
  </joint>

  <link name="steer_right_rear_link">
    <visual>
      <origin xyz="0.0 -0.027 -0.047" rpy="1.570796327 3.14159265359 0"/>
      <geometry>
        <mesh filename="package://aucar_description/mesh/xl430.dae"/>
      </geometry>
    </visual>
    <collision>
      <origin xyz="0.0 -0.027 -0.047" rpy="1.570796327 3.14159265359 0"/>
      <geometry>
        <mesh filename="package://aucar_description/mesh/xl430.dae"/>
      </geometry>
    </collision>
    <inertial>
      <origin xyz="0.0 -0.027 -0.047" rpy="1.570796327 3.14159265359 0"/>
      <mass value="1.5" />
      <inertia ixx="0.00391400" ixy="0.0" ixz="0.0"
               iyy="0.00391400" iyz="0.0"
               izz="0.00720300" />
    </inertial>
  </link>

  <joint name="wheel_right_rear_joint" type="continuous">
    <parent link="steer_right_rear_link"/>
    <child link="wheel_right_rear"/>
    <origin xyz="0.0 -0.008 -0.047" rpy="0 0 0"/>
    <axis xyz="0 -1 0"/>
  </joint>

  <link name="wheel_right_rear">
    <visual>
      <origin rpy="0 0 0" xyz="0 0.009 0"/>
      <geometry>
        <mesh filename="package://aucar_description/mesh/aucar_wheel.dae"/>
      </geometry>
    </visual>
    <collision>
      <origin rpy="0 0 0" xyz="0 0.009 0"/>
      <geometry>
        <mesh filename="package://aucar_description/mesh/aucar_wheel.dae"/>
      </geometry>
    </collision>
    <inertial>
      <origin rpy="0 0 0" xyz="0 0.009 0"/>
      <mass value="1.5" />
      <inertia ixx="0.00391400" ixy="0.0" ixz="0.0"
               iyy="0.00391400" iyz="0.0"
               izz="0.00720300" />
    </inertial>
  </link>   
</robot>
